{
  "comments": [
    {
      "key": {
        "uuid": "239024ca_3e8349c2",
        "filename": "test/136-daemon-jni-shutdown/daemon_jni_shutdown.cc",
        "patchSetId": 2
      },
      "lineNbr": 43,
      "author": {
        "id": 1015378
      },
      "writtenOn": "2016-06-08T18:09:41Z",
      "side": 1,
      "message": "If the thread is still running code and another thread calls DestroyJavaVM, I thought it DestroyJavaVM would block until it the threads are suspended?",
      "range": {
        "startLine": 43,
        "startChar": 2,
        "endLine": 43,
        "endChar": 22
      },
      "revId": "340f486aa0126facb67494449b5c2ee46a1a75e6",
      "serverId": "85c56323-6fa9-3386-8a01-6480fb634889",
      "unresolved": false
    },
    {
      "key": {
        "uuid": "239024ca_3ec8a9ba",
        "filename": "test/136-daemon-jni-shutdown/daemon_jni_shutdown.cc",
        "patchSetId": 2
      },
      "lineNbr": 43,
      "author": {
        "id": 1047769
      },
      "writtenOn": "2016-06-08T18:24:57Z",
      "side": 1,
      "message": "If this isn\u0027t entered the \u0027About to call exception check\u0027 will never be printed, which causes a fail. Also it seems that by faking up our own stack we can confuse those checks.",
      "parentUuid": "239024ca_3e8349c2",
      "range": {
        "startLine": 43,
        "startChar": 2,
        "endLine": 43,
        "endChar": 22
      },
      "revId": "340f486aa0126facb67494449b5c2ee46a1a75e6",
      "serverId": "85c56323-6fa9-3386-8a01-6480fb634889",
      "unresolved": false
    }
  ]
}